2025-08-30 11:09:06,166 CRIT Server 'unix_http_server' running without any HTTP authentication checking
2025-08-30 11:09:06,166 CRIT Server 'unix_http_server' running without any HTTP authentication checking
2025-08-30 11:09:06,166 INFO supervisord started with pid 69
2025-08-30 11:09:06,166 INFO supervisord started with pid 69
2025-08-30 11:09:07,169 INFO spawned: 'awx-config-watcher' with pid 72
2025-08-30 11:09:07,169 INFO spawned: 'awx-config-watcher' with pid 72
2025-08-30 11:09:07,171 INFO spawned: 'nginx' with pid 73
2025-08-30 11:09:07,171 INFO spawned: 'nginx' with pid 73
2025-08-30 11:09:07,181 INFO spawned: 'uwsgi' with pid 74
2025-08-30 11:09:07,181 INFO spawned: 'uwsgi' with pid 74
2025-08-30 11:09:07,183 INFO spawned: 'daphne' with pid 75
2025-08-30 11:09:07,183 INFO spawned: 'daphne' with pid 75
2025-08-30 11:09:07,189 INFO spawned: 'wsbroadcast' with pid 76
2025-08-30 11:09:07,189 INFO spawned: 'wsbroadcast' with pid 76
2025-08-30 11:09:07,197 INFO spawned: 'awx-rsyslogd' with pid 77
2025-08-30 11:09:07,197 INFO spawned: 'awx-rsyslogd' with pid 77
*** Starting uWSGI 2.0.18 (64bit) on [Sat Aug 30 11:09:07 2025] ***
compiled with version: 8.3.1 20191121 (Red Hat 8.3.1-5) on 26 January 2021 18:42:56
os: Linux-5.4.0-150-generic #167~18.04.1-Ubuntu SMP Wed May 24 00:51:42 UTC 2023
nodename: cbfd8ba775fa
machine: x86_64
clock source: unix
detected number of CPU cores: 2
current working directory: /var/lib/awx
detected binary path: /var/lib/awx/venv/awx/bin/uwsgi
!!! no internal routing support, rebuild with pcre support !!!
uWSGI running as root, you can use --uid/--gid/--chroot options
*** WARNING: you are running uWSGI as root !!! (use the --uid flag) *** 
your memory page size is 4096 bytes
 *** WARNING: you have enabled harakiri without post buffering. Slow upload could be rejected on post-unbuffered webservers *** 
detected max file descriptor number: 1048576
lock engine: pthread robust mutexes
thunder lock: disabled (you can enable it with --thunder-lock)
uwsgi socket 0 bound to TCP address 127.0.0.1:8050 fd 3
uWSGI running as root, you can use --uid/--gid/--chroot options
*** WARNING: you are running uWSGI as root !!! (use the --uid flag) *** 
Python version: 3.6.8 (default, Aug 24 2020, 17:57:11)  [GCC 8.3.1 20191121 (Red Hat 8.3.1-5)]
rsyslogd: cannot create '/var/run/awx-rsyslog/rsyslog.sock': No such file or directory [v8.1911.0-7.el8 try https://www.rsyslog.com/e/2176 ]
rsyslogd: imuxsock does not run because we could not aquire any socket  [v8.1911.0-7.el8]
rsyslogd: activation of module imuxsock failed [v8.1911.0-7.el8]
rsyslogd: error writing pid file (creation stage)
: No such file or directory
rsyslogd: run failed with error -3000 (see rsyslog.h or try https://www.rsyslog.com/e/3000 to learn what that number means)
*** Python threads support is disabled. You can enable it with --enable-threads ***
2025-08-30 11:09:07,269 INFO exited: awx-rsyslogd (exit status 1; not expected)
2025-08-30 11:09:07,269 INFO exited: awx-rsyslogd (exit status 1; not expected)
Python main interpreter initialized at 0x24a94c0
uWSGI running as root, you can use --uid/--gid/--chroot options
*** WARNING: you are running uWSGI as root !!! (use the --uid flag) *** 
your server socket listen backlog is limited to 100 connections
your mercy for graceful operations on workers is 60 seconds
mapped 609552 bytes (595 KB) for 5 cores
*** Operational MODE: preforking ***
uWSGI running as root, you can use --uid/--gid/--chroot options
*** WARNING: you are running uWSGI as root !!! (use the --uid flag) *** 
*** uWSGI is running in multiple interpreter mode ***
spawned uWSGI master process (pid: 74)
spawned uWSGI worker 1 (pid: 80, cores: 1)
spawned uWSGI worker 2 (pid: 81, cores: 1)
spawned uWSGI worker 3 (pid: 82, cores: 1)
spawned uWSGI worker 4 (pid: 83, cores: 1)
spawned uWSGI worker 5 (pid: 84, cores: 1)
READY
2025-08-30 11:09:08,659 INFO success: awx-config-watcher entered RUNNING state, process has stayed up for > than 1 seconds (startsecs)
2025-08-30 11:09:08,659 INFO success: awx-config-watcher entered RUNNING state, process has stayed up for > than 1 seconds (startsecs)
2025-08-30 11:09:08,659 INFO success: nginx entered RUNNING state, process has stayed up for > than 1 seconds (startsecs)
2025-08-30 11:09:08,659 INFO success: nginx entered RUNNING state, process has stayed up for > than 1 seconds (startsecs)
2025-08-30 11:09:08,660 INFO success: uwsgi entered RUNNING state, process has stayed up for > than 1 seconds (startsecs)
2025-08-30 11:09:08,660 INFO success: uwsgi entered RUNNING state, process has stayed up for > than 1 seconds (startsecs)
2025-08-30 11:09:08,660 INFO success: daphne entered RUNNING state, process has stayed up for > than 1 seconds (startsecs)
2025-08-30 11:09:08,660 INFO success: daphne entered RUNNING state, process has stayed up for > than 1 seconds (startsecs)
2025-08-30 11:09:08,660 INFO success: wsbroadcast entered RUNNING state, process has stayed up for > than 1 seconds (startsecs)
2025-08-30 11:09:08,660 INFO success: wsbroadcast entered RUNNING state, process has stayed up for > than 1 seconds (startsecs)
2025-08-30 11:09:08,661 INFO spawned: 'awx-rsyslogd' with pid 92
2025-08-30 11:09:08,661 INFO spawned: 'awx-rsyslogd' with pid 92
rsyslogd: cannot create '/var/run/awx-rsyslog/rsyslog.sock': No such file or directory [v8.1911.0-7.el8 try https://www.rsyslog.com/e/2176 ]
rsyslogd: imuxsock does not run because we could not aquire any socket  [v8.1911.0-7.el8]
rsyslogd: activation of module imuxsock failed [v8.1911.0-7.el8]
rsyslogd: error writing pid file (creation stage)
: No such file or directory
rsyslogd: run failed with error -3000 (see rsyslog.h or try https://www.rsyslog.com/e/3000 to learn what that number means)
2025-08-30 11:09:09,691 INFO success: awx-rsyslogd entered RUNNING state, process has stayed up for > than 1 seconds (startsecs)
2025-08-30 11:09:09,691 INFO success: awx-rsyslogd entered RUNNING state, process has stayed up for > than 1 seconds (startsecs)
2025-08-30 11:09:09,692 INFO exited: awx-rsyslogd (exit status 1; not expected)
2025-08-30 11:09:09,692 INFO exited: awx-rsyslogd (exit status 1; not expected)
2025-08-30 11:09:10,694 INFO spawned: 'awx-rsyslogd' with pid 107
2025-08-30 11:09:10,694 INFO spawned: 'awx-rsyslogd' with pid 107
rsyslogd: cannot create '/var/run/awx-rsyslog/rsyslog.sock': No such file or directory [v8.1911.0-7.el8 try https://www.rsyslog.com/e/2176 ]
rsyslogd: imuxsock does not run because we could not aquire any socket  [v8.1911.0-7.el8]
rsyslogd: activation of module imuxsock failed [v8.1911.0-7.el8]
rsyslogd: error writing pid file (creation stage)
: No such file or directory
rsyslogd: run failed with error -3000 (see rsyslog.h or try https://www.rsyslog.com/e/3000 to learn what that number means)
2025-08-30 11:09:11,716 INFO success: awx-rsyslogd entered RUNNING state, process has stayed up for > than 1 seconds (startsecs)
2025-08-30 11:09:11,716 INFO success: awx-rsyslogd entered RUNNING state, process has stayed up for > than 1 seconds (startsecs)
2025-08-30 11:09:11,716 INFO exited: awx-rsyslogd (exit status 1; not expected)
2025-08-30 11:09:11,716 INFO exited: awx-rsyslogd (exit status 1; not expected)
2025-08-30 11:09:12,719 INFO spawned: 'awx-rsyslogd' with pid 108
2025-08-30 11:09:12,719 INFO spawned: 'awx-rsyslogd' with pid 108
rsyslogd: cannot create '/var/run/awx-rsyslog/rsyslog.sock': No such file or directory [v8.1911.0-7.el8 try https://www.rsyslog.com/e/2176 ]
rsyslogd: imuxsock does not run because we could not aquire any socket  [v8.1911.0-7.el8]
rsyslogd: activation of module imuxsock failed [v8.1911.0-7.el8]
rsyslogd: error writing pid file (creation stage)
: No such file or directory
rsyslogd: run failed with error -3000 (see rsyslog.h or try https://www.rsyslog.com/e/3000 to learn what that number means)
WSGI app 0 (mountpoint='') ready in 6 seconds on interpreter 0x24a94c0 pid: 83 (default app)
2025-08-30 11:09:13,628 INFO exited: awx-rsyslogd (exit status 1; not expected)
2025-08-30 11:09:13,628 INFO exited: awx-rsyslogd (exit status 1; not expected)
WSGI app 0 (mountpoint='') ready in 6 seconds on interpreter 0x24a94c0 pid: 84 (default app)
2025-08-30 11:09:13,662 ERROR    Database settings are not available, using defaults.
Traceback (most recent call last):
  File "/var/lib/awx/venv/awx/lib/python3.6/site-packages/redis/connection.py", line 552, in connect
    sock = self._connect()
  File "/var/lib/awx/venv/awx/lib/python3.6/site-packages/redis/connection.py", line 905, in _connect
    sock.connect(self.path)
FileNotFoundError: [Errno 2] No such file or directory

During handling of the above exception, another exception occurred:

Traceback (most recent call last):
  File "/var/lib/awx/venv/awx/lib/python3.6/site-packages/awx/main/routing.py", line 20, in __init__
    for k in r.scan_iter('asgi:*', 500):
  File "/var/lib/awx/venv/awx/lib/python3.6/site-packages/redis/client.py", line 2097, in scan_iter
    count=count, _type=_type)
  File "/var/lib/awx/venv/awx/lib/python3.6/site-packages/redis/client.py", line 2077, in scan
    return self.execute_command('SCAN', *pieces)
  File "/var/lib/awx/venv/awx/lib/python3.6/site-packages/redis/client.py", line 875, in execute_command
    conn = self.connection or pool.get_connection(command_name, **options)
  File "/var/lib/awx/venv/awx/lib/python3.6/site-packages/redis/connection.py", line 1185, in get_connection
    connection.connect()
  File "/var/lib/awx/venv/awx/lib/python3.6/site-packages/redis/connection.py", line 557, in connect
    raise ConnectionError(self._error_message(e))
redis.exceptions.ConnectionError: Error 2 connecting to unix socket: /var/run/redis/redis.sock. No such file or directory.

During handling of the above exception, another exception occurred:

Traceback (most recent call last):
  File "/var/lib/awx/venv/awx/lib/python3.6/site-packages/django/db/backends/base/base.py", line 217, in ensure_connection
    self.connect()
  File "/var/lib/awx/venv/awx/lib/python3.6/site-packages/django/db/backends/base/base.py", line 195, in connect
    self.connection = self.get_new_connection(conn_params)
  File "/var/lib/awx/venv/awx/lib/python3.6/site-packages/django/db/backends/postgresql/base.py", line 178, in get_new_connection
    connection = Database.connect(**conn_params)
  File "/var/lib/awx/venv/awx/lib/python3.6/site-packages/psycopg2/__init__.py", line 126, in connect
    conn = _connect(dsn, connection_factory=connection_factory, **kwasync)
psycopg2.OperationalError: could not connect to server: Connection refused
	Is the server running on host "localhost" (127.0.0.1) and accepting
	TCP/IP connections on port 5432?
could not connect to server: Cannot assign requested address
	Is the server running on host "localhost" (::1) and accepting
	TCP/IP connections on port 5432?


The above exception was the direct cause of the following exception:

Traceback (most recent call last):
  File "/var/lib/awx/venv/awx/lib/python3.6/site-packages/awx/conf/settings.py", line 81, in _ctit_db_wrapper
    yield
  File "/var/lib/awx/venv/awx/lib/python3.6/site-packages/awx/conf/settings.py", line 441, in __getattr__
    value = self._get_local(name)
  File "/var/lib/awx/venv/awx/lib/python3.6/site-packages/awx/conf/settings.py", line 356, in _get_local
    self._preload_cache()
  File "/var/lib/awx/venv/awx/lib/python3.6/site-packages/awx/conf/settings.py", line 317, in _preload_cache
    for setting in Setting.objects.filter(key__in=settings_to_cache.keys(), user__isnull=True).order_by('pk'):
  File "/var/lib/awx/venv/awx/lib/python3.6/site-packages/django/db/models/query.py", line 274, in __iter__
    self._fetch_all()
  File "/var/lib/awx/venv/awx/lib/python3.6/site-packages/django/db/models/query.py", line 1242, in _fetch_all
    self._result_cache = list(self._iterable_class(self))
  File "/var/lib/awx/venv/awx/lib/python3.6/site-packages/django/db/models/query.py", line 55, in __iter__
    results = compiler.execute_sql(chunked_fetch=self.chunked_fetch, chunk_size=self.chunk_size)
  File "/var/lib/awx/venv/awx/lib/python3.6/site-packages/django/db/models/sql/compiler.py", line 1140, in execute_sql
    cursor = self.connection.cursor()
  File "/var/lib/awx/venv/awx/lib/python3.6/site-packages/django/db/backends/base/base.py", line 256, in cursor
    return self._cursor()
  File "/var/lib/awx/venv/awx/lib/python3.6/site-packages/django/db/backends/base/base.py", line 233, in _cursor
    self.ensure_connection()
  File "/var/lib/awx/venv/awx/lib/python3.6/site-packages/django/db/backends/base/base.py", line 217, in ensure_connection
    self.connect()
  File "/var/lib/awx/venv/awx/lib/python3.6/site-packages/django/db/utils.py", line 89, in __exit__
    raise dj_exc_value.with_traceback(traceback) from exc_value
  File "/var/lib/awx/venv/awx/lib/python3.6/site-packages/django/db/backends/base/base.py", line 217, in ensure_connection
    self.connect()
  File "/var/lib/awx/venv/awx/lib/python3.6/site-packages/django/db/backends/base/base.py", line 195, in connect
    self.connection = self.get_new_connection(conn_params)
  File "/var/lib/awx/venv/awx/lib/python3.6/site-packages/django/db/backends/postgresql/base.py", line 178, in get_new_connection
    connection = Database.connect(**conn_params)
  File "/var/lib/awx/venv/awx/lib/python3.6/site-packages/psycopg2/__init__.py", line 126, in connect
    conn = _connect(dsn, connection_factory=connection_factory, **kwasync)
django.db.utils.OperationalError: could not connect to server: Connection refused
	Is the server running on host "localhost" (127.0.0.1) and accepting
	TCP/IP connections on port 5432?
could not connect to server: Cannot assign requested address
	Is the server running on host "localhost" (::1) and accepting
	TCP/IP connections on port 5432?

WSGI app 0 (mountpoint='') ready in 6 seconds on interpreter 0x24a94c0 pid: 80 (default app)
2025-08-30 11:09:13,677 ERROR    Database settings are not available, using defaults.
Traceback (most recent call last):
  File "/var/lib/awx/venv/awx/lib/python3.6/site-packages/redis/connection.py", line 552, in connect
    sock = self._connect()
  File "/var/lib/awx/venv/awx/lib/python3.6/site-packages/redis/connection.py", line 905, in _connect
    sock.connect(self.path)
FileNotFoundError: [Errno 2] No such file or directory

During handling of the above exception, another exception occurred:

Traceback (most recent call last):
  File "/var/lib/awx/venv/awx/lib/python3.6/site-packages/awx/main/routing.py", line 20, in __init__
    for k in r.scan_iter('asgi:*', 500):
  File "/var/lib/awx/venv/awx/lib/python3.6/site-packages/redis/client.py", line 2097, in scan_iter
    count=count, _type=_type)
  File "/var/lib/awx/venv/awx/lib/python3.6/site-packages/redis/client.py", line 2077, in scan
    return self.execute_command('SCAN', *pieces)
  File "/var/lib/awx/venv/awx/lib/python3.6/site-packages/redis/client.py", line 875, in execute_command
    conn = self.connection or pool.get_connection(command_name, **options)
  File "/var/lib/awx/venv/awx/lib/python3.6/site-packages/redis/connection.py", line 1185, in get_connection
    connection.connect()
  File "/var/lib/awx/venv/awx/lib/python3.6/site-packages/redis/connection.py", line 557, in connect
    raise ConnectionError(self._error_message(e))
redis.exceptions.ConnectionError: Error 2 connecting to unix socket: /var/run/redis/redis.sock. No such file or directory.

During handling of the above exception, another exception occurred:

Traceback (most recent call last):
  File "/var/lib/awx/venv/awx/lib/python3.6/site-packages/django/db/backends/base/base.py", line 217, in ensure_connection
    self.connect()
  File "/var/lib/awx/venv/awx/lib/python3.6/site-packages/django/db/backends/base/base.py", line 195, in connect
    self.connection = self.get_new_connection(conn_params)
  File "/var/lib/awx/venv/awx/lib/python3.6/site-packages/django/db/backends/postgresql/base.py", line 178, in get_new_connection
    connection = Database.connect(**conn_params)
  File "/var/lib/awx/venv/awx/lib/python3.6/site-packages/psycopg2/__init__.py", line 126, in connect
    conn = _connect(dsn, connection_factory=connection_factory, **kwasync)
psycopg2.OperationalError: could not connect to server: Connection refused
	Is the server running on host "localhost" (127.0.0.1) and accepting
	TCP/IP connections on port 5432?
could not connect to server: Cannot assign requested address
	Is the server running on host "localhost" (::1) and accepting
	TCP/IP connections on port 5432?


The above exception was the direct cause of the following exception:

Traceback (most recent call last):
  File "/var/lib/awx/venv/awx/lib/python3.6/site-packages/awx/conf/settings.py", line 81, in _ctit_db_wrapper
    yield
  File "/var/lib/awx/venv/awx/lib/python3.6/site-packages/awx/conf/settings.py", line 441, in __getattr__
    value = self._get_local(name)
  File "/var/lib/awx/venv/awx/lib/python3.6/site-packages/awx/conf/settings.py", line 383, in _get_local
    setting = Setting.objects.filter(key=name, user__isnull=True).order_by('pk').first()
  File "/var/lib/awx/venv/awx/lib/python3.6/site-packages/django/db/models/query.py", line 653, in first
    for obj in (self if self.ordered else self.order_by('pk'))[:1]:
  File "/var/lib/awx/venv/awx/lib/python3.6/site-packages/django/db/models/query.py", line 274, in __iter__
    self._fetch_all()
  File "/var/lib/awx/venv/awx/lib/python3.6/site-packages/django/db/models/query.py", line 1242, in _fetch_all
    self._result_cache = list(self._iterable_class(self))
  File "/var/lib/awx/venv/awx/lib/python3.6/site-packages/django/db/models/query.py", line 55, in __iter__
    results = compiler.execute_sql(chunked_fetch=self.chunked_fetch, chunk_size=self.chunk_size)
  File "/var/lib/awx/venv/awx/lib/python3.6/site-packages/django/db/models/sql/compiler.py", line 1140, in execute_sql
    cursor = self.connection.cursor()
  File "/var/lib/awx/venv/awx/lib/python3.6/site-packages/django/db/backends/base/base.py", line 256, in cursor
    return self._cursor()
  File "/var/lib/awx/venv/awx/lib/python3.6/site-packages/django/db/backends/base/base.py", line 233, in _cursor
    self.ensure_connection()
  File "/var/lib/awx/venv/awx/lib/python3.6/site-packages/django/db/backends/base/base.py", line 217, in ensure_connection
    self.connect()
  File "/var/lib/awx/venv/awx/lib/python3.6/site-packages/django/db/utils.py", line 89, in __exit__
    raise dj_exc_value.with_traceback(traceback) from exc_value
  File "/var/lib/awx/venv/awx/lib/python3.6/site-packages/django/db/backends/base/base.py", line 217, in ensure_connection
    self.connect()
  File "/var/lib/awx/venv/awx/lib/python3.6/site-packages/django/db/backends/base/base.py", line 195, in connect
    self.connection = self.get_new_connection(conn_params)
  File "/var/lib/awx/venv/awx/lib/python3.6/site-packages/django/db/backends/postgresql/base.py", line 178, in get_new_connection
    connection = Database.connect(**conn_params)
  File "/var/lib/awx/venv/awx/lib/python3.6/site-packages/psycopg2/__init__.py", line 126, in connect
    conn = _connect(dsn, connection_factory=connection_factory, **kwasync)
django.db.utils.OperationalError: could not connect to server: Connection refused
	Is the server running on host "localhost" (127.0.0.1) and accepting
	TCP/IP connections on port 5432?
could not connect to server: Cannot assign requested address
	Is the server running on host "localhost" (::1) and accepting
	TCP/IP connections on port 5432?

2025-08-30 11:09:13,619 WARNING  encountered an error communicating with redis.
Traceback (most recent call last):
  File "/var/lib/awx/venv/awx/lib/python3.6/site-packages/redis/connection.py", line 552, in connect
    sock = self._connect()
  File "/var/lib/awx/venv/awx/lib/python3.6/site-packages/redis/connection.py", line 905, in _connect
    sock.connect(self.path)
FileNotFoundError: [Errno 2] No such file or directory

During handling of the above exception, another exception occurred:

Traceback (most recent call last):
  File "/var/lib/awx/venv/awx/bin/daphne", line 8, in <module>
    sys.exit(CommandLineInterface.entrypoint())
  File "/var/lib/awx/venv/awx/lib/python3.6/site-packages/daphne/cli.py", line 191, in entrypoint
    cls().run(sys.argv[1:])
  File "/var/lib/awx/venv/awx/lib/python3.6/site-packages/daphne/cli.py", line 252, in run
    application = import_by_path(args.application)
  File "/var/lib/awx/venv/awx/lib/python3.6/site-packages/daphne/utils.py", line 12, in import_by_path
    target = importlib.import_module(module_path)
  File "/var/lib/awx/venv/awx/lib64/python3.6/importlib/__init__.py", line 126, in import_module
    return _bootstrap._gcd_import(name[level:], package, level)
  File "<frozen importlib._bootstrap>", line 994, in _gcd_import
  File "<frozen importlib._bootstrap>", line 971, in _find_and_load
  File "<frozen importlib._bootstrap>", line 955, in _find_and_load_unlocked
  File "<frozen importlib._bootstrap>", line 665, in _load_unlocked
  File "<frozen importlib._bootstrap_external>", line 678, in exec_module
  File "<frozen importlib._bootstrap>", line 219, in _call_with_frames_removed
  File "/var/lib/awx/venv/awx/lib/python3.6/site-packages/awx/asgi.py", line 38, in <module>
    channel_layer = get_default_application()
  File "/var/lib/awx/venv/awx/lib/python3.6/site-packages/channels/routing.py", line 29, in get_default_application
    module = importlib.import_module(path)
  File "/var/lib/awx/venv/awx/lib64/python3.6/importlib/__init__.py", line 126, in import_module
    return _bootstrap._gcd_import(name[level:], package, level)
  File "<frozen importlib._bootstrap>", line 994, in _gcd_import
  File "<frozen importlib._bootstrap>", line 971, in _find_and_load
  File "<frozen importlib._bootstrap>", line 955, in _find_and_load_unlocked
  File "<frozen importlib._bootstrap>", line 665, in _load_unlocked
  File "<frozen importlib._bootstrap_external>", line 678, in exec_module
  File "<frozen importlib._bootstrap>", line 219, in _call_with_frames_removed
  File "/var/lib/awx/venv/awx/lib/python3.6/site-packages/awx/main/routing.py", line 36, in <module>
    URLRouter(websocket_urlpatterns)
  File "/var/lib/awx/venv/awx/lib/python3.6/site-packages/awx/main/routing.py", line 25, in __init__
    raise e
  File "/var/lib/awx/venv/awx/lib/python3.6/site-packages/awx/main/routing.py", line 20, in __init__
    for k in r.scan_iter('asgi:*', 500):
  File "/var/lib/awx/venv/awx/lib/python3.6/site-packages/redis/client.py", line 2097, in scan_iter
    count=count, _type=_type)
  File "/var/lib/awx/venv/awx/lib/python3.6/site-packages/redis/client.py", line 2077, in scan
    return self.execute_command('SCAN', *pieces)
  File "/var/lib/awx/venv/awx/lib/python3.6/site-packages/redis/client.py", line 875, in execute_command
    conn = self.connection or pool.get_connection(command_name, **options)
  File "/var/lib/awx/venv/awx/lib/python3.6/site-packages/redis/connection.py", line 1185, in get_connection
    connection.connect()
  File "/var/lib/awx/venv/awx/lib/python3.6/site-packages/redis/connection.py", line 557, in connect
    raise ConnectionError(self._error_message(e))
redis.exceptions.ConnectionError: Error 2 connecting to unix socket: /var/run/redis/redis.sock. No such file or directory.
WSGI app 0 (mountpoint='') ready in 6 seconds on interpreter 0x24a94c0 pid: 82 (default app)
WSGI app 0 (mountpoint='') ready in 6 seconds on interpreter 0x24a94c0 pid: 81 (default app)
2025-08-30 11:09:13,901 INFO exited: daphne (exit status 1; not expected)
2025-08-30 11:09:13,901 INFO exited: daphne (exit status 1; not expected)
dockeradm@sddo-vm:~/awx$ 
